Workbook
Name _______________________apr98: #REF!
Name _______________________apr99: #REF!
Name _______________________dec98: #REF!
Name _______________________feb98: #REF!
Name _______________________feb99: #REF!
Name _______________________jan98: #REF!
Name _______________________jan99: #REF!
Name _______________________jun99: #REF!
Name _______________________mar98: #REF!
Name _______________________mar99: #REF!
Name _______________________mei99: #REF!
Name _______________________mm02: #REF!
Name _______________________mm2: #REF!
Name _______________________nov98: #REF!
Name _______________________sep98: #REF!
Name ______________________CON1: #REF!
Name ______________________des06: #REF!
Name ______________________INC2: #REF!
Name ______________________IRB99: #REF!
Name ______________________ji1: #REF!
Name ______________________SA1: #REF!
Name ______________________YW1: #REF!
Name _____________________Apr98: #REF!
Name _____________________Apr99: #REF!
Name _____________________CON1: #REF!
Name _____________________DAT10: #REF!
Name _____________________DAT11: #REF!
Name _____________________DAT12: #REF!
Name _____________________DAT13: #REF!
Name _____________________DAT2: #REF!
Name _____________________DAT3: #REF!
Name _____________________DAT4: #REF!
Name _____________________DAT5: #REF!
Name _____________________DAT6: #REF!
Name _____________________DAT7: #REF!
Name _____________________DAT8: #REF!
Name _____________________DAT9: #REF!
Name _____________________Dec98: #REF!
Name _____________________des06: #REF!
Name _____________________Feb98: #REF!
Name _____________________Feb99: #REF!
Name _____________________INC2: #REF!
Name _____________________IRB99: #REF!
Name _____________________Jan98: #REF!
Name _____________________Jan99: #REF!
Name _____________________ji1: #REF!
Name _____________________JUN99: #REF!
Name _____________________Mar98: #REF!
Name _____________________Mar99: #REF!
Name _____________________MEI99: #REF!
Name _____________________mm02: #REF!
Name _____________________mm2: #REF!
Name _____________________Nov98: #REF!
Name _____________________SA1: #REF!
Name _____________________Sep98: #REF!
Name _____________________YW1: #REF!
Name ____________________apr98: #REF!
Name ____________________apr99: #REF!
Name ____________________CON1: #REF!
Name ____________________DAT1: #REF!

Sheet Penjelasan Rumus
B1: Penjelasan Rumus Penilaian (sederhana)
B3: 1. Capaian = REALISASI dibandingkan TARGET (untuk KPI apapun)
B4: • Maximize (makin tinggi makin baik): Capaian = Realisasi / Target
B5: • Minimize (makin rendah/cepat makin baik): Capaian = Target / Realisasi
B6: • Kalau realisasi sudah MEMENUHI atau MELEBIHI target (termasuk serah lebih cepat) -> Capaian = penuh (1,1).
B7: Rumus: =IF(realisasi<=target, 1,1, IFERROR(target/realisasi,0)) [untuk minimize, mis. rkap & kecelakaan]
B9: 2. Skor = Capaian x Bobot (maksimum 1,1 x Bobot)
B10: Rumus: =MIN(1,1*bobot ; capaian*bobot)
B12: 3. Contoh RKAP (yang tadi salah)
B13: Target serah 30/09/2025, realisasi 30/08/2025 (LEBIH CEPAT) -> memenuhi -> Capaian 1,1 -> skor penuh.
B14: Sebelumnya rumus lama (date-tier) memberi 0 untuk serah setelah Juni, padahal target 30 Sep. Itu sudah diperbaiki.
B16: 4. Beberapa perspektif (Korporat, Region Head, SEVP Operation, SEVP Business Support)
B17: Capaian sama; yang beda hanya bobot tiap jabatan, sehingga skornya beda. Rumus skor tetap sama.

Sheet Temuan & Perbaikan
A1: Temuan Audit & Perbaikan — Sheet N4 (PTPN IV)
A3: No | B3: Status | C3: Lokasi | D3: Temuan / Tindakan | E3: Dampak
A4: 1 | B4: DIPERBAIKI | C4: RKAP — semua N4 (blok atas, kolom CP/CQ/S/T) | D4: Capaian RKAP diubah ke aturan realisasi-vs-target: serah pada/atau sebelum target = penuh. Rumus date-tier lama yang memberi 0 dihapus. | E4: RKAP kini bernilai penuh; naik di perspektif Region Head & SEVP BS
A5: 2 | B5: DIPERBAIKI | C5: Kecelakaan Kerja Fatal — N4R4/5/6/7 | D5: Rekor nol kecelakaan: capaian 0 -> 1,1 (penuh). | E5: Skor Korporat Regional 4–7 naik +1,1 (mengalir ke Rekap)
A6: 3 | B6: DATA DIBENAHI | C6: N4R2 & N4R4 (tanggal serah RKAP) | D6: Tanggal serah berformat TEKS diubah jadi tanggal asli (31/07/2025; 30/09/2025). | E6: Agar bisa dihitung
A7: 4 | B7: PERLU DICEK KAMU | C7: N4R5 (tanggal serah RKAP) | D7: Isi selnya "1", bukan tanggal. Diasumsikan memenuhi (skor penuh), tapi tolong isi tanggal serah aslinya. | E7: Data sumber tidak lengkap
A8: 5 | B8: PERLU KEPUTUSAN | C8: Bobot RKAP di perspektif SEVP Operation = 0 | D8: Karena bobotnya 0, perbaikan RKAP TIDAK menambah kolom "Korporat" di Rekap (kolom itu menarik dari total SEVP Operation). Pastikan apakah bobot 0 ini disengaja. | E8: Headline Korporat tidak berubah dari RKAP
A9: 6 | B9: PERLU PERHATIAN | C9: Skor per-orang RH/SEVP di Rekap (dari "Kertas Kerja") | D9: Nilainya DIKETIK MANUAL (hardcoded), tidak tertaut ke sheet N4. Jadi perbaikan di N4 tidak otomatis mengubahnya — perlu diperbarui manual bila ingin ikut. | E9: Risiko skor per-orang tidak sinkron
A10: 7 | B10: CATATAN STRUKTUR | C10: Semua sheet N4 | D10: Tiap sheet punya DUA blok KPI kembar: blok atas (tampilan) menghitung capaian, blok bawah (scorecard) yang masuk total. Struktur antar-regional juga tidak seragam. | E10: Sumber utama kerawanan salah
A11: 8 | B11: SUDAH DIBERSIHKAN | C11: KINRA (nama nyasar) & Cascad!A1 (referensi rusak) | D11: Sampah dihapus. | E11: Kerapian; 0 error
A12: 9 | B12: BERSIH ✔ | C12: Entitas (PTPN IV/I/III, SGN), 7 anak perusahaan, N1R1–R8 | D12: Tabel hasil capaian diperiksa: arah benar, skor=capaian×bobot (maks 1,1×bobot), konsisten antar perspektif, total cocok Rekap. | E12: Tidak ada error hitung

Sheet Rekap
A1: Rekapitulasi Nilai
K2: Penilaian SEVP
C3: Korporat | D3: Region Head | E3: SEVP Ops / 1 | F3: SEVP Ops 2 | G3: SEVP BS | K3: No | L3: Entitas Penugasan | M3: Nama | N3: Jabatan | O3: Nilai 2025 | P3: Keterangan
B4: PalmCo HO | C4: ='PTPN IV'!T29 -> 94.373244 | K4: 1 | L4: PTPN I - Supporting Co HO | M4: Teddy Yunirman Danas | N4: Direktur Utama | O4: ='Kertas Kerja'!L6*12/'Kertas Kerja'!K6 -> 81.73 | P4: Skor Direktur menyusul
B5: Regional 1 | C5: =N4R1!T94 -> 89.727552 | D5: ='Kertas Kerja'!L44*12/'Kertas Kerja'!K44 -> 88.593044 | E5: ='Kertas Kerja'!L45*12/'Kertas Kerja'!K45 -> 89.727552 | F5: ='Kertas Kerja'!L46*12/'Kertas Kerja'!K46 -> 89.727552 | G5: ='Kertas Kerja'!L48*12/'Kertas Kerja'!K48 -> 87.493371 | K5: 2 | L5: PTPN I - Supporting Co HO | M5: Fauzi Omar | N5: Direktur Operasional | O5: ='Kertas Kerja'!L7*12/'Kertas Kerja'!K7 -> 83.56 | P5: Skor Direktur menyusul
B6: Regional 2 | C6: =N4R2!T100 -> 88.78702 | D6: ='Kertas Kerja'!L53*12/'Kertas Kerja'!K53 -> 87.528879 | E6: ='Kertas Kerja'!L51*12/'Kertas Kerja'!K51 -> 88.78702 | F6: ='Kertas Kerja'!L52*12/'Kertas Kerja'!K52 -> 88.78702 | G6: ='Kertas Kerja'!L55*12/'Kertas Kerja'!K55 -> 85.464029 | K6: 3 | L6: PTPN I - Supporting Co HO | M6: Landi Rizaldi Mangaweang | N6: Direktur Pemasaran dan Aset | O6: ='Kertas Kerja'!L8*12/'Kertas Kerja'!K8 -> 81.41 | P6: Skor Direktur menyusul
B7: Regional 3 | C7: =N4R3!T108 -> 90.239473 | E7: ='Kertas Kerja'!L57*12/'Kertas Kerja'!K57 -> 90.239473 | G7: ='Kertas Kerja'!L58*12/'Kertas Kerja'!K58 -> 88.893676 | K7: 4 | L7: PTPN I - Supporting Co HO | M7: Doni P Gandamihardja | N7: Direktur Keuangan dan Manajemen Risiko | O7: ='Kertas Kerja'!L9*12/'Kertas Kerja'!K9 -> 84.38 | P7: Skor Direktur menyusul
B8: Regional 4 | C8: =N4R4!T101 -> 80.595579 | D8: ='Kertas Kerja'!L60*12/'Kertas Kerja'!K60 -> 79.96698 | E8: ='Kertas Kerja'!L64*12/'Kertas Kerja'!K64 -> 80.595579 | G8: ='Kertas Kerja'!L63*12/'Kertas Kerja'!K63 -> 77.041735 | K8: 5 | L8: PTPN I - Supporting Co HO | M8: Siwi Peni | N8: Direktur SDM dan TI | O8: ='Kertas Kerja'!L10*12/'Kertas Kerja'!K10 -> 84.55 | P8: Skor Direktur menyusul
B9: Regional 5 | C9: =N4R5!T90 -> 75.639951 | D9: ='Kertas Kerja'!L65*12/'Kertas Kerja'!K65 -> 75.800929 | E9: ='Kertas Kerja'!L66*12/'Kertas Kerja'!K66 -> 75.639951 | F9: ='Kertas Kerja'!L68*12/'Kertas Kerja'!K68 -> 75.639951 | G9: ='Kertas Kerja'!L70*12/'Kertas Kerja'!K70 -> 74.484656 | K9: 6 | L9: PTPN I - Supporting Co HO | M9: Tio Handoko | N9: Direktur Hubungan Kelembagaan | O9: ='Kertas Kerja'!L11*12/'Kertas Kerja'!K11 -> 85.58 | P9: Skor Direktur menyusul
B10: Regional 6 | C10: =N4R6!T83 -> 85.485773 | D10: ='Kertas Kerja'!L71*12/'Kertas Kerja'!K71 -> 83.512711 | E10: ='Kertas Kerja'!L72*12/'Kertas Kerja'!K72 -> 85.485773 | G10: ='Kertas Kerja'!L71*12/'Kertas Kerja'!K71 -> 83.512711 | K10: 7 | L10: PTPN I - Regional 1 | M10: Didik Prasetyo | N10: Region Head R1 | O10: ='Kertas Kerja'!L12*12/'Kertas Kerja'!K12 -> 95.415993
B11: Regional 7 | C11: =N4R7!T72 -> 77.278198 | D11: ='Kertas Kerja'!L76*12/'Kertas Kerja'!K76 -> 77.3547 | E11: ='Kertas Kerja'!L78*12/'Kertas Kerja'!K78 -> 77.278198 | G11: ='Kertas Kerja'!L77*12/'Kertas Kerja'!K77 -> 77.399186 | K11: 8 | L11: PTPN I - Regional 1 | M11: Wispramono Budiman | N11: SEVP Business Support R1 | O11: ='Kertas Kerja'!L13*12/'Kertas Kerja'!K13 -> 96.051929
K12: 9 | L12: PTPN I - Regional 1 | M12: Wispramono Budiman | N12: Plt Region Head R1 | O12: ='Kertas Kerja'!L14*12/'Kertas Kerja'!K14 -> 95.4
C13: Korporat | D13: Region Head | E13: SEVP Ops | F13: SEVP BS | G13: SEVP Aset | K13: 10 | L13: PTPN I - Regional 1 | M13: Ganda Wiatmaja | N13: SEVP Aset R1 | O13: ='Kertas Kerja'!L15*12/'Kertas Kerja'!K15 -> 96.051929
B14: SuppCo HO | C14: ='PTPN I'!U29 -> 81.726071 | K14: 11 | L14: PTPN I - Regional 2 | M14: Desmanto | N14: Region Head R2 | O14: ='Kertas Kerja'!L16*12/'Kertas Kerja'!K16 -> 81.971293
B15: Regional 1 | C15: =N1R1!O36 -> 93.508259 | D15: ='Kertas Kerja'!L12*12/'Kertas Kerja'!K12 -> 95.415993 | F15: ='Kertas Kerja'!L13*12/'Kertas Kerja'!K13 -> 96.051929 | G15: ='Kertas Kerja'!L15*12/'Kertas Kerja'!K15 -> 96.051929 | K15: 12 | L15: PTPN I - Regional 2 | M15: Iyan Heryanto | N15: SEVP Operation R2 | O15: ='Kertas Kerja'!L17*12/'Kertas Kerja'!K17 -> 80.074079
B16: Regional 2 | C16: =N1R2!O51 -> 85.73579 | D16: ='Kertas Kerja'!L16*12/'Kertas Kerja'!K16 -> 81.971293 | E16: ='Kertas Kerja'!L17*12/'Kertas Kerja'!K17 -> 80.074079 | F16: ='Kertas Kerja'!L18*12/'Kertas Kerja'!K18 -> 85.58976 | G16: ='Kertas Kerja'!L19*12/'Kertas Kerja'!K19 -> 85.58976 | K16: 13 | L16: PTPN I - Regional 2 | M16: Okta Kurniawan | N16: SEVP Business Support R2 | O16: ='Kertas Kerja'!L18*12/'Kertas Kerja'!K18 -> 85.58976
B17: Regional 3 | C17: =N1R3!O52 -> 89.82181 | D17: ='Kertas Kerja'!L20*12/'Kertas Kerja'!K20 -> 93.716363 | E17: ='Kertas Kerja'!L21*12/'Kertas Kerja'!K21 -> 91.091047 | K17: 14 | L17: PTPN I - Regional 2 | M17: Pulung Rinandoro | N17: SEVP Aset R2 | O17: ='Kertas Kerja'!L19*12/'Kertas Kerja'!K19 -> 85.58976
B18: Regional 4 | C18: =N1R4!O40 -> 78.91782 | D18: ='Kertas Kerja'!L22*12/'Kertas Kerja'!K22 -> 78.014818 | F18: ='Kertas Kerja'!L23*12/'Kertas Kerja'!K23 -> 76.285714 | K18: 15 | L18: PTPN I - Regional 3 | M18: Tri Septiono | N18: Region Head R3 | O18: ='Kertas Kerja'!L20*12/'Kertas Kerja'!K20 -> 93.716363
B19: Regional 5 | C19: =N1R5!O53 -> 91.736908 | D19: ='Kertas Kerja'!L25*12/'Kertas Kerja'!K25 -> 94.20555 | E19: ='Kertas Kerja'!L26*12/'Kertas Kerja'!K26 -> 91.818108 | F19: ='Kertas Kerja'!L27*12/'Kertas Kerja'!K27 -> 96.033058 | K19: 16 | L19: PTPN I - Regional 3 | M19: Budiyono | N19: SEVP Operation R3 | O19: ='Kertas Kerja'!L21*12/'Kertas Kerja'!K21 -> 91.091047
B20: Regional 6 | K20: 17 | L20: PTPN I - Regional 4 | M20: Subagiyo | N20: Region Head R4 | O20: ='Kertas Kerja'!L22*12/'Kertas Kerja'!K22 -> 78.014818
B21: Regional 7 | C21: =N1R7!O49 -> 82.061196 | D21: ='Kertas Kerja'!L28*12/'Kertas Kerja'!K28 -> 82.927896 | E21: ='Kertas Kerja'!L30*12/'Kertas Kerja'!K30 -> 82.078565 | F21: ='Kertas Kerja'!L29*12/'Kertas Kerja'!K29 -> 83.943905 | K21: 18 | L21: PTPN I - Regional 4 | M21: Subagiyo | N21: SEVP Business Support R5 | O21: ='Kertas Kerja'!L23*12/'Kertas Kerja'!K23 -> 76.285714
B22: Regional 8 | C22: =N1R8!O40 -> 80.194877 | D22: ='Kertas Kerja'!L32*12/'Kertas Kerja'!K32 -> 80.724997 | E22: ='Kertas Kerja'!L35*12/'Kertas Kerja'!K35 -> 81.1915 | F22: ='Kertas Kerja'!L33*12/'Kertas Kerja'!K33 -> 80.258495 | K22: 19 | L22: PTPN I - Regional 4 | M22: Subagiyo | N22: Ptr Region Head R5 | O22: ='Kertas Kerja'!L24*12/'Kertas Kerja'!K24 -> 78
K23: 20 | L23: PTPN I - Regional 5 | M23: Winarto | N23: Region Head R5 | O23: ='Kertas Kerja'!L25*12/'Kertas Kerja'!K25 -> 94.20555
C24: Korporat | D24: SEVP Koordinator KSO | E24: SEVP Operation | F24: SEVP Strategic Business | K24: 21 | L24: PTPN I - Regional 5 | M24: Asep Sontani | N24: SEVP Operation R5 | O24: ='Kertas Kerja'!L26*12/'Kertas Kerja'!K26 -> 91.818108
B25: SGN | C25: ='PT SGN'!AJ29 -> 73.663065 | D25: ='Kertas Kerja'!L87*12/'Kertas Kerja'!K87 -> 80.874179 | E25: ='Kertas Kerja'!L90*12/'Kertas Kerja'!K90 -> 80.874179 | F25: ='Kertas Kerja'!L85*12/'Kertas Kerja'!K85 -> 80.874179 | K25: 22 | L25: PTPN I - Regional 5 | M25: Benny Sandjaya | N25: SEVP Business Support R5 | O25: ='Kertas Kerja'!L27*12/'Kertas Kerja'!K27 -> 96.033058
K26: 23 | L26: PTPN I - Regional 7 | M26: Tuhu Bangun | N26: Regional Head R7 | O26: ='Kertas Kerja'!L28*12/'Kertas Kerja'!K28 -> 82.927896
C27: Korporat | D27: SEVP Ops | E27: SEVP BS | F27: SEVP Riset | G27: SEVP Ops 2 | K27: 24 | L27: PTPN I - Regional 7 | M27: Bambang Agustian | N27: SEVP Business Support R7 | O27: ='Kertas Kerja'!L29*12/'Kertas Kerja'!K29 -> 83.943905
B28: KPBN | C28: =KPBN!R29 -> 61.784112 | D28: =KPBN!Y29 -> 67.267769 | E28: =KPBN!AB29 -> 55.92232 | K28: 25 | L28: PTPN I - Regional 7 | M28: Wiyoso | N28: SEVP Operation R7 | O28: ='Kertas Kerja'!L30*12/'Kertas Kerja'!K30 -> 82.078565
B29: LPPAN | C29: =LPP!Q30 -> 101.12832 | D29: =LPP!X30 -> 104.94083 | E29: =LPP!AA30 -> 97.775816 | K29: 26 | L29: PTPN I - Regional 7 | M29: Iskandar Dewantara | N29: SEVP Busines Support R7 | O29: ='Kertas Kerja'!L31*12/'Kertas Kerja'!K31 -> 83.943905
B30: IKN | C30: =IKN!R33 -> 81.424634 | D30: =IKN!Y33 -> 84.960581 | K30: 27 | L30: PTPN I - Regional 8 | M30: R Tulus Panduwidjaja | N30: Regional Head R8 | O30: ='Kertas Kerja'!L32*12/'Kertas Kerja'!K32 -> 80.724997
B31: KINRA | C31: =KINRA!T35 -> 89.77349 | D31: =KINRA!AA35 -> 84.408548 | E31: =KINRA!AD35 -> 86.492949 | K31: 28 | L31: PTPN I - Regional 8 | M31: Maalun Lamau | N31: SEVP Business Support R8 | O31: ='Kertas Kerja'!L33*12/'Kertas Kerja'!K33 -> 80.258495
B32: SPMN | C32: =SPMN!R42 -> 91.026695 | D32: =SPMN!Y42 -> 93.027368 | K32: 29 | M32: Maalun Lamau | N32: Plt. Region Head R8 | O32: ='Kertas Kerja'!L34*12/'Kertas Kerja'!K34 -> 80.724997
B33: RPN | C33: =RPN!R33 -> 88.099317 | D33: =RPN!Y33 -> 87.009253 | E33: =RPN!AB33 -> 87.643837 | F33: =RPN!Y33 -> 87.009253 | G33: =RPN!Y33 -> 87.009253 | K33: 30 | L33: PTPN I - Regional 8 | M33: Misran | N33: SEVP Operation R8 | O33: ='Kertas Kerja'!L35*12/'Kertas Kerja'!K35 -> 81.1915
B34: BIN | C34: =BIN!R39 -> 64.782115 | D34: =BIN!Y39 -> 68.927603 | K34: 31 | L34: PTPN IV - Palm Co HO | M34: Jatmiko Krisna Santosa | N34: Direktur Utama | O34: ='Kertas Kerja'!L36*12/'Kertas Kerja'!K36 -> 89.8 | P34: Skor Direktur menyusul
K35: 32 | L35: PTPN IV - Palm Co HO | M35: Rizal H Damanik | N35: Direktur Operasional | O35: ='Kertas Kerja'!L37*12/'Kertas Kerja'!K37 -> 86.26 | P35: Skor Direktur menyusul
K36: 33 | L36: PTPN IV - Palm Co HO | M36: Ryanto Wisnuardhy | N36: Direktur Pemasaran dan Komersial | O36: ='Kertas Kerja'!L38*12/'Kertas Kerja'!K38 -> 96.56 | P36: Skor Direktur menyusul
K37: 34 | L37: PTPN IV - Palm Co HO | M37: Hilda Savitri | N37: Direktur Keuangan dan Manajemen Risiko | O37: ='Kertas Kerja'!L39*12/'Kertas Kerja'!K39 -> 93.89 | P37: Skor Direktur menyusul
K38: 35 | L38: PTPN IV - Palm Co HO | M38: Suhendri | N38: Direktur SDM dan TI | O38: ='Kertas Kerja'!L40*12/'Kertas Kerja'!K40 -> 87.43 | P38: Skor Direktur menyusul
K39: 36 | L39: PTPN IV - Palm Co HO | M39: Irwan Perangin Angin | N39: Direktur Hubungan Kelembagaan | O39: ='Kertas Kerja'!L41*12/'Kertas Kerja'!K41 -> 90.84 | P39: Skor Direktur menyusul
A40: No | B40: Anak Perusahaan | C40: Status LHEK | D40: Tanggal | K40: 37 | L40: PTPN IV - Palm Co HO | M40: Ugun Untaryo | N40: Direktur Strategic dan Sustainability | O40: ='Kertas Kerja'!L42*12/'Kertas Kerja'!K42 -> 85.4 | P40: Skor Direktur menyusul
...

Sheet List
A3: No | B3: PTPN | C3: Nama Pejabat | D3: Jabatan | E3: Periode Menjabat Tahun 2025 | G3: Hari | H3: Bulan | I3: Asal Entitas | J3: Status | K3: NIK
E4: Awal Menjabat | F4: Akhir Menjabat
A5: Supporting Co
A6: 1 | B6: PTPN I - Supporting Co HO | C6: Teddy Yunirman Danas | D6: Direktur Utama | E6: 45658 | F6: 46022 | G6: =DATEDIF(E6,F6,"d")+1 -> 365 | H6: =DATEDIF(E6,F6,"M") + IF(DATEDIF(E6,F6,"MD")>=15,1,0) -> 12 | I6: PTPN I - Supporting Co HO | J6: PKWT
A7: 2 | B7: PTPN I - Supporting Co HO | C7: Fauzi Omar | D7: Direktur Operasional | E7: 45658 | F7: 46022 | G7: =DATEDIF(E7,F7,"d")+1 -> 365 | H7: =DATEDIF(E7,F7,"M") + IF(DATEDIF(E7,F7,"MD")>=15,1,0) -> 12 | I7: PTPN I - Supporting Co HO | J7: PKWT | N7: 1 | O7: N3
A8: =A7+1 -> 3 | B8: PTPN I - Supporting Co HO | C8: Landi Rizaldi Mangaweang | D8: Direktur Pemasaran dan Aset | E8: 45658 | F8: 46022 | G8: =DATEDIF(E8,F8,"d")+1 -> 365 | H8: =DATEDIF(E8,F8,"M") + IF(DATEDIF(E8,F8,"MD")>=15,1,0) -> 12 | I8: PTPN I - Supporting Co HO | J8: PKWT | N8: 2 | O8: N1
A9: =A8+1 -> 4 | B9: PTPN I - Supporting Co HO | C9: Doni P Gandamihardja | D9: Direktur Keuangan dan Manajemen Risiko | E9: 45658 | F9: 46022 | G9: =DATEDIF(E9,F9,"d")+1 -> 365 | H9: =DATEDIF(E9,F9,"M") + IF(DATEDIF(E9,F9,"MD")>=15,1,0) -> 12 | I9: PTPN I - Supporting Co HO | J9: PKWT | N9: 3 | O9: N4
A10: =A9+1 -> 5 | B10: PTPN I - Supporting Co HO | C10: Siwi Peni | D10: Direktur SDM dan TI | E10: 45658 | F10: 46022 | G10: =DATEDIF(E10,F10,"d")+1 -> 365 | H10: =DATEDIF(E10,F10,"M") + IF(DATEDIF(E10,F10,"MD")>=15,1,0) -> 12 | I10: PTPN I - Supporting Co HO | J10: PKWT | N10: 4 | O10: SGN
A11: =A10+1 -> 6 | B11: PTPN I - Supporting Co HO | C11: Tio Handoko | D11: Direktur Hubungan Kelembagaan | E11: 45658 | F11: 46022 | G11: =DATEDIF(E11,F11,"d")+1 -> 365 | H11: =DATEDIF(E11,F11,"M") + IF(DATEDIF(E11,F11,"MD")>=15,1,0) -> 12 | I11: PTPN I - Supporting Co HO | J11: PKWT | N11: 5 | O11: RPN
A12: 7 | B12: PTPN I - Regional 1 | C12: Didik Prasetyo | D12: Region Head R1 | E12: 45658 | F12: 45961 | G12: =DATEDIF(E12,F12,"d")+1 -> 304 | H12: =DATEDIF(E12,F12,"M") + IF(DATEDIF(E12,F12,"MD")>=15,1,0) -> 10 | I12: PTPN I - Regional 1 | J12: PKWT | N12: 6 | O12: KPBN
A13: =A12+1 -> 8 | B13: PTPN I - Regional 1 | C13: Wispramono Budiman | D13: SEVP Business Support R1 | E13: 45658 | F13: 46022 | G13: =DATEDIF(E13,F13,"d")+1 -> 365 | H13: =DATEDIF(E13,F13,"M") + IF(DATEDIF(E13,F13,"MD")>=15,1,0) -> 12 | I13: PTPN I - Regional 1 | J13: PKWTT | K13: 8100026 | N13: 7 | O13: LPPAN
C14: Wispramono Budiman | D14: Plt Region Head R1 | E14: 45962 | F14: 46022 | G14: =DATEDIF(E14,F14,"d")+1 -> 61 | H14: =DATEDIF(E14,F14,"M") + IF(DATEDIF(E14,F14,"MD")>=15,1,0) -> 2 | I14: PTPN I - Regional 1 | J14: PKWTT | K14: 8100026 | N14: 8 | O14: BIN
A15: =A13+1 -> 9 | B15: PTPN I - Regional 1 | C15: Ganda Wiatmaja | D15: SEVP Aset R1 | E15: 45662 | F15: 46022 | G15: =DATEDIF(E15,F15,"d")+1 -> 361 | H15: =DATEDIF(E15,F15,"M") + IF(DATEDIF(E15,F15,"MD")>=15,1,0) -> 12 | I15: PTPN I - Regional 1 | J15: PKWTT | K15: 3023289 | N15: 9 | O15: SPMN
A16: =A15+1 -> 10 | B16: PTPN I - Regional 2 | C16: Desmanto | D16: Region Head R2 | E16: 45658 | F16: 46022 | G16: =DATEDIF(E16,F16,"d")+1 -> 365 | H16: =DATEDIF(E16,F16,"M") + IF(DATEDIF(E16,F16,"MD")>=15,1,0) -> 12 | I16: PTPN I - Regional 2 | J16: PKWT | N16: 10 | O16: IKN
A17: =A16+1 -> 11 | B17: PTPN I - Regional 2 | C17: Iyan Heryanto | D17: SEVP Operation R2 | E17: 45658 | F17: 46022 | G17: =DATEDIF(E17,F17,"d")+1 -> 365 | H17: =DATEDIF(E17,F17,"M") + IF(DATEDIF(E17,F17,"MD")>=15,1,0) -> 12 | I17: PTPN I - Regional 2 | J17: PKWTT | K17: 13002790 | N17: 11 | O17: KINRA
A18: =A17+1 -> 12 | B18: PTPN I - Regional 2 | C18: Okta Kurniawan | D18: SEVP Business Support R2 | E18: 45658 | F18: 46022 | G18: =DATEDIF(E18,F18,"d")+1 -> 365 | H18: =DATEDIF(E18,F18,"M") + IF(DATEDIF(E18,F18,"MD")>=15,1,0) -> 12 | I18: PTPN I - Regional 2 | J18: PKWTT | K18: 7001902
A19: =A18+1 -> 13 | B19: PTPN I - Regional 2 | C19: Pulung Rinandoro | D19: SEVP Aset R2 | E19: 45658 | F19: 46022 | G19: =DATEDIF(E19,F19,"d")+1 -> 365 | H19: =DATEDIF(E19,F19,"M") + IF(DATEDIF(E19,F19,"MD")>=15,1,0) -> 12 | I19: PTPN I - Regional 2 | J19: PKWT
A20: =A19+1 -> 14 | B20: PTPN I - Regional 3 | C20: Tri Septiono | D20: Region Head R3 | E20: 45658 | F20: 46022 | G20: =DATEDIF(E20,F20,"d")+1 -> 365 | H20: =DATEDIF(E20,F20,"M") + IF(DATEDIF(E20,F20,"MD")>=15,1,0) -> 12 | I20: PTPN I - Regional 3 | J20: PKWT
A21: =A20+1 -> 15 | B21: PTPN I - Regional 3 | C21: Budiyono | D21: SEVP Operation R3 | E21: 45658 | F21: 46022 | G21: =DATEDIF(E21,F21,"d")+1 -> 365 | H21: =DATEDIF(E21,F21,"M") + IF(DATEDIF(E21,F21,"MD")>=15,1,0) -> 12 | I21: PTPN I - Regional 3 | J21: PKWTT | K21: 9000134
A22: =A21+1 -> 16 | B22: PTPN I - Regional 4 | C22: Subagiyo | D22: Region Head R4 | E22: 45658 | F22: 45808 | G22: =DATEDIF(E22,F22,"d")+1 -> 151 | H22: =DATEDIF(E22,F22,"M") + IF(DATEDIF(E22,F22,"MD")>=15,1,0) -> 5 | I22: PTPN I - Regional 5 | J22: PKWTT | K22: 11000154
C23: Subagiyo | D23: SEVP Business Support R5 | E23: 45809 | F23: 46022 | G23: =DATEDIF(E23,F23,"d")+1 -> 214 | H23: =DATEDIF(E23,F23,"M") + IF(DATEDIF(E23,F23,"MD")>=15,1,0) -> 7 | I23: PTPN I - Regional 5 | J23: PKWTT | K23: 11000154
C24: Subagiyo | D24: Ptr Region Head R5 | E24: 45992 | F24: 46022 | G24: =DATEDIF(E24,F24,"d")+1 -> 31 | H24: =DATEDIF(E24,F24,"M") + IF(DATEDIF(E24,F24,"MD")>=15,1,0) -> 1 | I24: PTPN I - Regional 5 | J24: PKWTT | K24: 11000154
A25: 17 | B25: PTPN I - Regional 5 | C25: Winarto | D25: Region Head R5 | E25: 45658 | F25: 45991 | G25: =DATEDIF(E25,F25,"d")+1 -> 334 | H25: =DATEDIF(E25,F25,"M") + IF(DATEDIF(E25,F25,"MD")>=15,1,0) -> 11 | I25: PTPN I - Regional 5 | J25: PKWTT | K25: 12020544
A26: =A25+1 -> 18 | B26: PTPN I - Regional 5 | C26: Asep Sontani | D26: SEVP Operation R5 | E26: 45658 | F26: 46022 | G26: =DATEDIF(E26,F26,"d")+1 -> 365 | H26: =DATEDIF(E26,F26,"M") + IF(DATEDIF(E26,F26,"MD")>=15,1,0) -> 12 | I26: PTPN I - Regional 5 | J26: PKWTT | K26: 9005498
A27: =A26+1 -> 19 | B27: PTPN I - Regional 5 | C27: Benny Sandjaya | D27: SEVP Business Support R5 | E27: 45658 | F27: 45808 | G27: =DATEDIF(E27,F27,"d")+1 -> 151 | H27: =DATEDIF(E27,F27,"M") + IF(DATEDIF(E27,F27,"MD")>=15,1,0) -> 5 | I27: PTPN I - Regional 5 | J27: PKWTT | K27: 10000045
A28: =A27+1 -> 20 | B28: PTPN I - Regional 7 | C28: Tuhu Bangun | D28: Regional Head R7 | E28: 45658 | F28: 46022 | G28: =DATEDIF(E28,F28,"d")+1 -> 365 | H28: =DATEDIF(E28,F28,"M") + IF(DATEDIF(E28,F28,"MD")>=15,1,0) -> 12 | I28: PTPN I - Regional 7 | J28: PKWT
A29: =A28+1 -> 21 | B29: PTPN I - Regional 7 | C29: Bambang Agustian | D29: SEVP Business Support R7 | E29: 45658 | F29: 45808 | G29: =DATEDIF(E29,F29,"d")+1 -> 151 | H29: =DATEDIF(E29,F29,"M") + IF(DATEDIF(E29,F29,"MD")>=15,1,0) -> 5 | I29: PTPN I - Regional 7 | J29: PKWTT | K29: 4009842
A30: =A29+1 -> 22 | B30: PTPN I - Regional 7 | C30: Wiyoso | D30: SEVP Operation R7 | E30: 45658 | F30: 46022 | G30: =DATEDIF(E30,F30,"d")+1 -> 365 | H30: =DATEDIF(E30,F30,"M") + IF(DATEDIF(E30,F30,"MD")>=15,1,0) -> 12 | I30: PTPN I - Regional 7 | J30: PKWTT | K30: 7003199
A31: =A30+1 -> 23 | B31: PTPN I - Regional 7 | C31: Iskandar Dewantara | D31: SEVP Busines Support R7 | E31: 45809 | F31: 46022 | G31: =DATEDIF(E31,F31,"d")+1 -> 214 | H31: =DATEDIF(E31,F31,"M") + IF(DATEDIF(E31,F31,"MD")>=15,1,0) -> 7 | I31: PTPN I - Regional 7 | J31: PKWTT | K31: 4000040
A32: =A31+1 -> 24 | B32: PTPN I - Regional 8 | C32: R Tulus Panduwidjaja | D32: Regional Head R8 | E32: 45658 | F32: 45808 | G32: =DATEDIF(E32,F32,"d")+1 -> 151 | H32: =DATEDIF(E32,F32,"M") + IF(DATEDIF(E32,F32,"MD")>=15,1,0) -> 5 | I32: PTPN I - Regional 8 | J32: PKWT
A33: =A32+1 -> 25 | B33: PTPN I - Regional 8 | C33: Maalun Lamau | D33: SEVP Business Support R8 | E33: 45658 | F33: 46022 | G33: =DATEDIF(E33,F33,"d")+1 -> 365 | H33: =DATEDIF(E33,F33,"M") + IF(DATEDIF(E33,F33,"MD")>=15,1,0) -> 12 | I33: PTPN I - Regional 8 | J33: PKWTT | K33: 14000204
C34: Maalun Lamau | D34: Plt. Region Head R8 | E34: 45658 | F34: 46022 | G34: =DATEDIF(E34,F34,"d")+1 -> 365 | H34: =DATEDIF(E34,F34,"M") + IF(DATEDIF(E34,F34,"MD")>=15,1,0) -> 12 | I34: PTPN I - Regional 8 | J34: PKWTT | K34: 14000204
A35: 26 | B35: PTPN I - Regional 8 | C35: Misran | D35: SEVP Operation R8 | E35: 45809 | F35: 46022 | G35: =DATEDIF(E35,F35,"d")+1 -> 214 | H35: =DATEDIF(E35,F35,"M") + IF(DATEDIF(E35,F35,"MD")>=15,1,0) -> 7 | I35: PTPN I - Regional 8 | J35: PKWTT
A39: Palm Co
A40: 1 | B40: PTPN IV - Palm Co HO | C40: Jatmiko Krisna Santosa | D40: Direktur Utama | E40: 45658 | F40: 46022 | G40: =DATEDIF(E40,F40,"d")+1 -> 365 | H40: =DATEDIF(E40,F40,"M") + IF(DATEDIF(E40,F40,"MD")>=15,1,0) -> 12 | I40: PTPN IV - Palm Co HO | J40: PKWT
A41: 2 | B41: PTPN IV - Palm Co HO | C41: Rizal H Damanik | D41: Direktur Operasional | E41: 45658 | F41: 45823 | G41: =DATEDIF(E41,F41,"d")+1 -> 166 | H41: =DATEDIF(E41,F41,"M") + IF(DATEDIF(E41,F41,"MD")>=15,1,0) -> 5 | I41: PTPN IV - Palm Co HO | J41: PKWT
A42: 3 | B42: PTPN IV - Palm Co HO | C42: Ryanto Wisnuardhy | D42: Direktur Pemasaran dan Komersial | E42: 45658 | F42: 45823 | G42: =DATEDIF(E42,F42,"d")+1 -> 166 | H42: =DATEDIF(E42,F42,"M") + IF(DATEDIF(E42,F42,"MD")>=15,1,0) -> 5 | I42: PTPN IV - Palm Co HO | J42: PKWT
A43: 4 | B43: PTPN IV - Palm Co HO | C43: Hilda Savitri | D43: Direktur Keuangan dan Manajemen Risiko | E43: 45658 | F43: 46022 | G43: =DATEDIF(E43,F43,"d")+1 -> 365 | H43: =DATEDIF(E43,F43,"M") + IF(DATEDIF(E43,F43,"MD")>=15,1,0) -> 12 | I43: PTPN IV - Palm Co HO | J43: PKWT
A44: 5 | B44: PTPN IV - Palm Co HO | C44: Suhendri | D44: Direktur SDM dan TI | E44: 45658 | F44: 46022 | G44: =DATEDIF(E44,F44,"d")+1 -> 365 | H44: =DATEDIF(E44,F44,"M") + IF(DATEDIF(E44,F44,"MD")>=15,1,0) -> 12 | I44: PTPN IV - Palm Co HO | J44: PKWT
A45: 6 | B45: PTPN IV - Palm Co HO | C45: Irwan Perangin Angin | D45: Direktur Hubungan Kelembagaan | E45: 45658 | F45: 45972 | G45: =DATEDIF(E45,F45,"d")+1 -> 315 | H45: =DATEDIF(E45,F45,"M") + IF(DATEDIF(E45,F45,"MD")>=15,1,0) -> 10 | I45: PTPN IV - Palm Co HO | J45: PKWT
...

Sheet Kertas Kerja
B4: Penilaian Direktur, Region Head & SEVP 2025
B5: No | C5: Entitas Penugasan | D5: Nama | E5: Jabatan | F5: Nilai 2025 | G5: Keterangan | H5: Awal Menjabat | I5: Akhir Menjabat | J5: Hari | K5: Bulan | L5: SKOR SEMENTARA | M5: Jabatan Rangkap?
B6: 1 | C6: PTPN I - Supporting Co HO | D6: Teddy Yunirman Danas | E6: Direktur Utama | G6: Skor Direktur menyusul | H6: 45658 | I6: 46022 | J6: =I6-H6+1 -> 365 | K6: =ROUND(J6/365*12,0) -> 12 | L6: ='PTPN I DIR'!H18*K6/12 -> 81.73 | M6: {=IF(SUMPRODUCT(($D$6:$D$121=D6)*($H$6:$H$121<I6)*($I$6:$I$121>H6))>1,"Rangkap","")}
B7: 2 | C7: PTPN I - Supporting Co HO | D7: Fauzi Omar | E7: Direktur Operasional | G7: Skor Direktur menyusul | H7: 45658 | I7: 46022 | J7: 365 | K7: 12 | L7: ='PTPN I DIR'!H100*K7/12 -> 83.56 | M7: {=IF(SUMPRODUCT(($D$6:$D$121=D7)*($H$6:$H$121<I7)*($I$6:$I$121>H7))>1,"Rangkap","")}
B8: 3 | C8: PTPN I - Supporting Co HO | D8: Landi Rizaldi Mangaweang | E8: Direktur Pemasaran dan Aset | G8: Skor Direktur menyusul | H8: 45658 | I8: 46022 | J8: 365 | K8: 12 | L8: ='PTPN I DIR'!H114*K8/12 -> 81.41 | M8: {=IF(SUMPRODUCT(($D$6:$D$121=D8)*($H$6:$H$121<I8)*($I$6:$I$121>H8))>1,"Rangkap","")}
B9: 4 | C9: PTPN I - Supporting Co HO | D9: Doni P Gandamihardja | E9: Direktur Keuangan dan Manajemen Risiko | G9: Skor Direktur menyusul | H9: 45658 | I9: 46022 | J9: 365 | K9: 12 | L9: ='PTPN I DIR'!H78*K9/12 -> 84.38 | M9: {=IF(SUMPRODUCT(($D$6:$D$121=D9)*($H$6:$H$121<I9)*($I$6:$I$121>H9))>1,"Rangkap","")}
B10: 5 | C10: PTPN I - Supporting Co HO | D10: Siwi Peni | E10: Direktur SDM dan TI | G10: Skor Direktur menyusul | H10: 45658 | I10: 46022 | J10: 365 | K10: 12 | L10: ='PTPN I DIR'!H38*K10/12 -> 84.55 | M10: {=IF(SUMPRODUCT(($D$6:$D$121=D10)*($H$6:$H$121<I10)*($I$6:$I$121>H10))>1,"Rangkap","")}
B11: 6 | C11: PTPN I - Supporting Co HO | D11: Tio Handoko | E11: Direktur Hubungan Kelembagaan | G11: Skor Direktur menyusul | H11: 45658 | I11: 46022 | J11: 365 | K11: 12 | L11: ='PTPN I DIR'!H59*K11/12 -> 85.58 | M11: {=IF(SUMPRODUCT(($D$6:$D$121=D11)*($H$6:$H$121<I11)*($I$6:$I$121>H11))>1,"Rangkap","")}
B12: 7 | C12: PTPN I - Regional 1 | D12: Didik Prasetyo | E12: Region Head R1 | H12: 45658 | I12: 45972 | J12: 304 | K12: 10 | L12: =N1R1!M60*K12/12 -> 79.513327 | M12: {=IF(SUMPRODUCT(($D$6:$D$121=D12)*($H$6:$H$121<I12)*($I$6:$I$121>H12))>1,"Rangkap","")}
A13: Oke | B13: 8 | C13: PTPN I - Regional 1 | D13: Wispramono Budiman | E13: SEVP Business Support R1 | H13: 45658 | I13: 46022 | J13: 365 | K13: 12 | L13: =N1R1!Q60*K13/12 -> 96.051929 | M13: {=IF(SUMPRODUCT(($D$6:$D$121=D13)*($H$6:$H$121<I13)*($I$6:$I$121>H13))>1,"Rangkap","")} -> Rangkap
B14: 9 | C14: PTPN I - Regional 1 | D14: Wispramono Budiman | E14: Plt Region Head R1 | H14: 45962 | I14: 46022 | J14: 61 | K14: 2 | L14: 15.9 | M14: {=IF(SUMPRODUCT(($D$6:$D$121=D14)*($H$6:$H$121<I14)*($I$6:$I$121>H14))>1,"Rangkap","")} -> Rangkap
B15: 10 | C15: PTPN I - Regional 1 | D15: Ganda Wiatmaja | E15: SEVP Aset R1 | H15: 45662 | I15: 46022 | J15: 361 | K15: 12 | L15: =N1R1!Q60*K15/12 -> 96.051929 | M15: {=IF(SUMPRODUCT(($D$6:$D$121=D15)*($H$6:$H$121<I15)*($I$6:$I$121>H15))>1,"Rangkap","")}
B16: 11 | C16: PTPN I - Regional 2 | D16: Desmanto | E16: Region Head R2 | H16: 45658 | I16: 46022 | J16: 365 | K16: 12 | L16: =N1R2!M87*K16/12 -> 81.971293 | M16: {=IF(SUMPRODUCT(($D$6:$D$121=D16)*($H$6:$H$121<I16)*($I$6:$I$121>H16))>1,"Rangkap","")}
B17: 12 | C17: PTPN I - Regional 2 | D17: Iyan Heryanto | E17: SEVP Operation R2 | H17: 45658 | I17: 46022 | J17: 365 | K17: 12 | L17: =N1R2!O87*K17/12 -> 80.074079 | M17: {=IF(SUMPRODUCT(($D$6:$D$121=D17)*($H$6:$H$121<I17)*($I$6:$I$121>H17))>1,"Rangkap","")}
B18: 13 | C18: PTPN I - Regional 2 | D18: Okta Kurniawan | E18: SEVP Business Support R2 | H18: 45658 | I18: 46022 | J18: 365 | K18: 12 | L18: =N1R2!Q87*K18/12 -> 85.58976 | M18: {=IF(SUMPRODUCT(($D$6:$D$121=D18)*($H$6:$H$121<I18)*($I$6:$I$121>H18))>1,"Rangkap","")}
B19: 14 | C19: PTPN I - Regional 2 | D19: Pulung Rinandoro | E19: SEVP Aset R2 | H19: 45658 | I19: 46022 | J19: 365 | K19: 12 | L19: =N1R2!Q87*K19/12 -> 85.58976 | M19: {=IF(SUMPRODUCT(($D$6:$D$121=D19)*($H$6:$H$121<I19)*($I$6:$I$121>H19))>1,"Rangkap","")}
B20: 15 | C20: PTPN I - Regional 3 | D20: Tri Septiono | E20: Region Head R3 | H20: 45658 | I20: 46022 | J20: 365 | K20: 12 | L20: =N1R3!M90*K20/12 -> 93.716363 | M20: {=IF(SUMPRODUCT(($D$6:$D$121=D20)*($H$6:$H$121<I20)*($I$6:$I$121>H20))>1,"Rangkap","")}
B21: 16 | C21: PTPN I - Regional 3 | D21: Budiyono | E21: SEVP Operation R3 | H21: 45658 | I21: 46022 | J21: 365 | K21: 12 | L21: =N1R3!O90*K21/12 -> 91.091047 | M21: {=IF(SUMPRODUCT(($D$6:$D$121=D21)*($H$6:$H$121<I21)*($I$6:$I$121>H21))>1,"Rangkap","")}
B22: 17 | C22: PTPN I - Regional 4 | D22: Subagiyo | E22: Region Head R4 | H22: 45658 | I22: 45808 | J22: 151 | K22: 5 | L22: =N1R4!M67*K22/12 -> 32.506174 | M22: {=IF(SUMPRODUCT(($D$6:$D$121=D22)*($H$6:$H$121<I22)*($I$6:$I$121>H22))>1,"Rangkap","")}
A23: turun | B23: 18 | C23: PTPN I - Regional 4 | D23: Subagiyo | E23: SEVP Business Support R5 | H23: 45809 | I23: 46022 | J23: 214 | K23: 7 | L23: 44.5 | M23: {=IF(SUMPRODUCT(($D$6:$D$121=D23)*($H$6:$H$121<I23)*($I$6:$I$121>H23))>1,"Rangkap","")} -> Rangkap
B24: 19 | C24: PTPN I - Regional 4 | D24: Subagiyo | E24: Plt. Region Head R5 | H24: 45992 | I24: 46022 | J24: 31 | K24: 1 | L24: 6.5 | M24: {=IF(SUMPRODUCT(($D$6:$D$121=D24)*($H$6:$H$121<I24)*($I$6:$I$121>H24))>1,"Rangkap","")} -> Rangkap
B25: 20 | C25: PTPN I - Regional 5 | D25: Winarto | E25: Region Head R5 | H25: 45658 | I25: 45991 | J25: 334 | K25: 11 | L25: =N1R5!M91*K25/12 -> 86.355088 | M25: {=IF(SUMPRODUCT(($D$6:$D$121=D25)*($H$6:$H$121<I25)*($I$6:$I$121>H25))>1,"Rangkap","")}
B26: 21 | C26: PTPN I - Regional 5 | D26: Asep Sontani | E26: SEVP Operation R5 | H26: 45658 | I26: 46022 | J26: 365 | K26: 12 | L26: =N1R5!O91*K26/12 -> 91.818108 | M26: {=IF(SUMPRODUCT(($D$6:$D$121=D26)*($H$6:$H$121<I26)*($I$6:$I$121>H26))>1,"Rangkap","")}
B27: 22 | C27: PTPN I - Regional 5 | D27: Benny Sandjaya | E27: SEVP Business Support R5 | H27: 45658 | I27: 45808 | J27: 151 | K27: 5 | L27: =N1R5!Q91*K27/12 -> 40.013774 | M27: {=IF(SUMPRODUCT(($D$6:$D$121=D27)*($H$6:$H$121<I27)*($I$6:$I$121>H27))>1,"Rangkap","")}
B28: 23 | C28: PTPN I - Regional 7 | D28: Tuhu Bangun | E28: Regional Head R7 | H28: 45658 | I28: 46022 | J28: 365 | K28: 12 | L28: =N1R7!M84*K28/12 -> 82.927896 | M28: {=IF(SUMPRODUCT(($D$6:$D$121=D28)*($H$6:$H$121<I28)*($I$6:$I$121>H28))>1,"Rangkap","")}
B29: 24 | C29: PTPN I - Regional 7 | D29: Bambang Agustian | E29: SEVP Business Support R7 | H29: 45658 | I29: 45808 | J29: 151 | K29: 5 | L29: =N1R7!Q84*K29/12 -> 34.976627 | M29: {=IF(SUMPRODUCT(($D$6:$D$121=D29)*($H$6:$H$121<I29)*($I$6:$I$121>H29))>1,"Rangkap","")}
B30: 25 | C30: PTPN I - Regional 7 | D30: Wiyoso | E30: SEVP Operation R7 | H30: 45658 | I30: 46022 | J30: 365 | K30: 12 | L30: =N1R7!O84*K30/12 -> 82.078565 | M30: {=IF(SUMPRODUCT(($D$6:$D$121=D30)*($H$6:$H$121<I30)*($I$6:$I$121>H30))>1,"Rangkap","")}
A31: KPBN | B31: 26 | C31: PTPN I - Regional 7 | D31: Iskandar Dewantara | E31: SEVP Busines Support R7 | H31: 45809 | I31: 46022 | J31: 214 | K31: 7 | L31: =N1R7!Q84*K31/12 -> 48.967278 | M31: {=IF(SUMPRODUCT(($D$6:$D$121=D31)*($H$6:$H$121<I31)*($I$6:$I$121>H31))>1,"Rangkap","")} -> Rangkap
B32: 27 | C32: PTPN I - Regional 8 | D32: R Tulus Panduwidjaja | E32: Regional Head R8 | H32: 45658 | I32: 45808 | J32: 151 | K32: 5 | L32: =N1R8!M67*K32/12 -> 33.635416 | M32: {=IF(SUMPRODUCT(($D$6:$D$121=D32)*($H$6:$H$121<I32)*($I$6:$I$121>H32))>1,"Rangkap","")}
B33: 28 | C33: PTPN I - Regional 8 | D33: Maalun Lamau | E33: SEVP Business Support R8 | H33: 45658 | I33: 46022 | J33: 365 | K33: 12 | L33: =N1R8!Q67*K33/12 -> 80.258495 | M33: {=IF(SUMPRODUCT(($D$6:$D$121=D33)*($H$6:$H$121<I33)*($I$6:$I$121>H33))>1,"Rangkap","")} -> Rangkap
B34: 29 | D34: Maalun Lamau | E34: Plt. Region Head R8 | H34: 45658 | I34: 46022 | J34: =I34-H34+1 -> 365 | K34: =ROUND(J34/365*12,0) -> 12 | L34: =N1R8!M67*K34/12 -> 80.724997 | M34: {=IF(SUMPRODUCT(($D$6:$D$121=D34)*($H$6:$H$121<I34)*($I$6:$I$121>H34))>1,"Rangkap","")} -> Rangkap
B35: 30 | C35: PTPN I - Regional 8 | D35: Misran | E35: SEVP Operation R8 | H35: 45809 | I35: 46022 | J35: 214 | K35: 7 | L35: =N1R8!O67*K35/12 -> 47.361708 | M35: {=IF(SUMPRODUCT(($D$6:$D$121=D35)*($H$6:$H$121<I35)*($I$6:$I$121>H35))>1,"Rangkap","")}
B36: 31 | C36: PTPN IV - Palm Co HO | D36: Jatmiko Krisna Santosa | E36: Direktur Utama | G36: Skor Direktur menyusul | H36: 45658 | I36: 46022 | J36: 365 | K36: 12 | L36: ='PTPN IV DIR'!K26*K36/12 -> 89.8 | M36: {=IF(SUMPRODUCT(($D$6:$D$121=D36)*($H$6:$H$121<I36)*($I$6:$I$121>H36))>1,"Rangkap","")}
B37: 32 | C37: PTPN IV - Palm Co HO | D37: Rizal H Damanik | E37: Direktur Operasional | G37: Skor Direktur menyusul | H37: 45658 | I37: 45823 | J37: 166 | K37: 5 | L37: ='PTPN IV DIR'!K53*K37/12 -> 35.941667 | M37: {=IF(SUMPRODUCT(($D$6:$D$121=D37)*($H$6:$H$121<I37)*($I$6:$I$121>H37))>1,"Rangkap","")}
B38: 33 | C38: PTPN IV - Palm Co HO | D38: Ryanto Wisnuardhy | E38: Direktur Pemasaran dan Komersial | G38: Skor Direktur menyusul | H38: 45658 | I38: 45823 | J38: 166 | K38: 5 | L38: ='PTPN IV DIR'!K72*K38/12 -> 40.233333 | M38: {=IF(SUMPRODUCT(($D$6:$D$121=D38)*($H$6:$H$121<I38)*($I$6:$I$121>H38))>1,"Rangkap","")}
B39: 34 | C39: PTPN IV - Palm Co HO | D39: Hilda Savitri | E39: Direktur Keuangan dan Manajemen Risiko | G39: Skor Direktur menyusul | H39: 45658 | I39: 46022 | J39: 365 | K39: 12 | L39: ='PTPN IV DIR'!K114*K39/12 -> 93.89 | M39: {=IF(SUMPRODUCT(($D$6:$D$121=D39)*($H$6:$H$121<I39)*($I$6:$I$121>H39))>1,"Rangkap","")}
B40: 35 | C40: PTPN IV - Palm Co HO | D40: Suhendri | E40: Direktur SDM dan TI | G40: Skor Direktur menyusul | H40: 45658 | I40: 46022 | J40: 365 | K40: 12 | L40: ='PTPN IV DIR'!K136*K40/12 -> 87.43 | M40: {=IF(SUMPRODUCT(($D$6:$D$121=D40)*($H$6:$H$121<I40)*($I$6:$I$121>H40))>1,"Rangkap","")}
B41: 36 | C41: PTPN IV - Palm Co HO | D41: Irwan Perangin Angin | E41: Direktur Hubungan Kelembagaan | G41: Skor Direktur menyusul | H41: 45658 | I41: 45972 | J41: 315 | K41: 10 | L41: ='PTPN IV DIR'!K158*K41/12 -> 75.7 | M41: {=IF(SUMPRODUCT(($D$6:$D$121=D41)*($H$6:$H$121<I41)*($I$6:$I$121>H41))>1,"Rangkap","")}
B42: 37 | C42: PTPN IV - Palm Co HO | D42: Ugun Untaryo | E42: Direktur Strategic dan Sustainability | G42: Skor Direktur menyusul | H42: 45658 | I42: 46022 | J42: 365 | K42: 12 | L42: ='PTPN IV DIR'!K91*K42/12 -> 85.4 | M42: {=IF(SUMPRODUCT(($D$6:$D$121=D42)*($H$6:$H$121<I42)*($I$6:$I$121>H42))>1,"Rangkap","")}
B43: 38 | C43: PTPN IV - Palm Co HO | D43: Rediman Silalahi | E43: SEVP Operation HO | G43: SEVP level HO - sumber skor belum ada | H43: 45962 | I43: 46022 | J43: 61 | K43: 2 | M43: {=IF(SUMPRODUCT(($D$6:$D$121=D43)*($H$6:$H$121<I43)*($I$6:$I$121>H43))>1,"Rangkap","")}
...

Sheet PTPN III (Persero)
A1: Key Performance Indicator PT Perkebunan Nusantara III (Persero)
A2: s.d. Desember 2025
V3: Cascade Penilaian Region Head & SEVP
A4: No. | B4: Key Performance Indicator | C4: ESG/C | D4: 88 PS | E4: Satuan | F4: Target 2025 | G4: Target s.d. Desember | H4: Realisasi s.d. Desember | I4: Polaritas | J4: Bobot | L4: Realisasi vs Target s.d. Desember | N4: Realisasi vs Target 2025 | P4: Target 2025 | Q4: Realisasi 2025 | R4: Bobot KPI | S4: % Capaian Realisasi | T4: Skor Realisasi KPI | V4: Region Head | Y4: SEVP Operation / Koordinator KSO / Operasional KSO / Aset | AB4: SEVP Business Support / Business Strategy
J5: Sub | K5: Total | L5: Sub | M5: Total | N5: Sub | O5: Total | V5: Bobot | W5: % Capaian | X5: Skor | Y5: Bobot | Z5: % Capaian | AA5: Skor | AB5: Bobot | AC5: % Capaian | AD5: Skor
A6: A. Nilai Ekonomi dan Sosial Untuk Indonesia | V6: =V7+V11+V15 -> 50 | W6: =IFERROR(X6/V6,0) -> 0.89834112 | X6: =X7+X11+X15 -> 44.917056 | Y6: =Y7+Y11+Y15 -> 50 | Z6: =IFERROR(AA6/Y6,0) -> 0.90772431 | AA6: =AA7+AA11+AA15 -> 45.386215 | AB6: =AB7+AB11+AB15 -> 50 | AC6: =IFERROR(AD6/AB6,0) -> 0.86950976 | AD6: =AD7+AD11+AD15 -> 43.475488
A7: A.1 Finansial | V7: =SUM(V8:V10) -> 20 | W7: =IFERROR(X7/V7,0) -> 0.825 | X7: =SUM(X8:X10) -> 16.5 | Y7: =SUM(Y8:Y10) -> 10 | Z7: =IFERROR(AA7/Y7,0) -> 0.77 | AA7: =SUM(AA8:AA10) -> 7.7 | AB7: =SUM(AB8:AB10) -> 30 | AC7: =IFERROR(AD7/AB7,0) -> 0.80666667 | AD7: =SUM(AD8:AD10) -> 24.2
A8: 1 | B8: EBITDA Margin | C8: C | E8: % | F8: 22.89 | G8: 22.89 | H8: 26.94 | I8: Maximize | J8: 8 | K8: =J8+J9+J10 -> 18 | L8: =IFERROR(MIN(1.1*J8,(H8/G8)*J8),0) -> 8.8 | M8: =SUM(L8:L10) -> 14.3 | N8: =IFERROR(MIN(1.1*J8,(H8/F8)*J8),0) -> 8.8 | O8: =SUM(N8:N10) -> 14.3 | P8: =F8 -> 22.89 | Q8: =H8 -> 26.94 | R8: =J8 -> 8 | S8: =IFERROR(IF(I8="Minimize",F8/H8,IF(F8<=0,IF(H8>=F8,1.1,0),H8/F8)),0) -> 1.1769332 | T8: =MIN(1.1*R8,S8*R8) -> 8.8 | V8: 9 | W8: =S8 -> 1.1769332 | X8: =MIN(1.1*V8,W8*V8) -> 9.9 | Y8: 4 | Z8: =S8 -> 1.1769332 | AA8: =MIN(1.1*Y8,Z8*Y8) -> 4.4 | AB8: 14 | AC8: =S8 -> 1.1769332 | AD8: =MIN(1.1*AB8,AC8*AB8) -> 15.4
A9: 2 | B9: ROIC >= WACC | C9: C | E9: % | F9: -1.34 | G9: -1.34 | H9: 0.44 | I9: Maximize | J9: 5 | L9: 5.5 | N9: 5.5 | P9: =F9 -> -1.34 | Q9: =H9 -> 0.44 | R9: =J9 -> 5 | S9: =IFERROR(IF(I9="Minimize",F9/H9,IF(F9<=0,IF(H9>=F9,1.1,0),H9/F9)),0) -> 1.1 | T9: =MIN(1.1*R9,S9*R9) -> 5.5 | V9: 6 | W9: =S9 -> 1.1 | X9: =MIN(1.1*V9,W9*V9) -> 6.6 | Y9: 3 | Z9: =S9 -> 1.1 | AA9: =MIN(1.1*Y9,Z9*Y9) -> 3.3 | AB9: 8 | AC9: =S9 -> 1.1 | AD9: =MIN(1.1*AB9,AC9*AB9) -> 8.8
A10: 3 | B10: Penyampaian LAI Tahun 2024 | C10: G | E10: Waktu | F10: 15/04/2025 | G10: 15/04/2025 | H10: 45861 | I10: Minimize | J10: 5 | L10: 0 | N10: =IFERROR(MIN(1.1*L10,(H10/J10)*L10),0) -> 0 | P10: =F10 -> 15/04/2025 | Q10: =H10 -> 45861 | R10: =J10 -> 5 | S10: =IFERROR(T10/R10,0) -> 0 | T10: =R10*IF(H10<DATE(2025,4,1),1.1,IF(H10<=DATE(2025,4,15),1,IF(H10<=DATE(2025,5,31),0.8,IF(H10<=DATE(2025,6,15),0.4,IF(H10<=DATE(2025,6,30),0.2,0))))) -> 0 | V10: 5 | W10: =S10 -> 0 | X10: =MIN(1.1*V10,W10*V10) -> 0 | Y10: 3 | Z10: =S10 -> 0 | AA10: =MIN(1.1*Y10,Z10*Y10) -> 0 | AB10: 8 | AC10: =S10 -> 0 | AD10: =MIN(1.1*AB10,AC10*AB10) -> 0
A11: A.2. Operasional | V11: =SUM(V12:V14) -> 20 | W11: =IFERROR(X11/V11,0) -> 0.91473527 | X11: =SUM(X12:X14) -> 18.294705 | Y11: =SUM(Y12:Y14) -> 30 | Z11: =IFERROR(AA11/Y11,0) -> 0.91879549 | AA11: =SUM(AA12:AA14) -> 27.563865 | AB11: =SUM(AB12:AB14) -> 10 | AC11: =IFERROR(AD11/AB11,0) -> 0.91531373 | AD11: =SUM(AD12:AD14) -> 9.1531373
A12: 4 | B12: Produktivitas CPO | C12: C | E12: Ton/Ha | F12: 5.43 | G12: 5.43 | H12: 4.8 | I12: Maximize | J12: 7 | K12: =SUM(J12+J13+J14) -> 21 | L12: =IFERROR(MIN(1.1*J12,(H12/G12)*J12),0) -> 6.1878453 | M12: =SUM(L12+L13+L14) -> 19.294705 | N12: =IFERROR(MIN(1.1*J12,(H12/F12)*J12),0) -> 6.1878453 | O12: =SUM(N12+N13+N14) -> 19.294705 | P12: =F12 -> 5.43 | Q12: =H12 -> 4.8 | R12: =J12 -> 7 | S12: =IFERROR(IF(I12="Minimize",F12/H12,IF(F12<=0,IF(H12>=F12,1.1,0),H12/F12)),0) -> 0.8839779 | T12: =MIN(1.1*R12,S12*R12) -> 6.1878453 | V12: 7 | W12: =S12 -> 0.8839779 | X12: =MIN(1.1*V12,W12*V12) -> 6.1878453 | Y12: 10 | Z12: =S12 -> 0.8839779 | AA12: =MIN(1.1*Y12,Z12*Y12) -> 8.839779 | AB12: 4 | AC12: =S12 -> 0.8839779 | AD12: =MIN(1.1*AB12,AC12*AB12) -> 3.5359116
A13: 5 | B13: Pencapaian Produksi Gula Untuk Mendukung Swasembada | C13: C | E13: Ton | F13: 1011621 | G13: 1011621 | H13: 882546.84 | I13: Maximize | J13: 7 | L13: =IFERROR(MIN(1.1*J13,(H13/G13)*J13),0) -> 6.1068601 | N13: =IFERROR(MIN(1.1*J13,(H13/F13)*J13),0) -> 6.1068601 | P13: =F13 -> 1011621 | Q13: =H13 -> 882546.84 | R13: =J13 -> 7 | S13: =IFERROR(IF(I13="Minimize",F13/H13,IF(F13<=0,IF(H13>=F13,1.1,0),H13/F13)),0) -> 0.87240858 | T13: =MIN(1.1*R13,S13*R13) -> 6.1068601 | V13: 7 | W13: =S13 -> 0.87240858 | X13: =MIN(1.1*V13,W13*V13) -> 6.1068601 | Y13: 10 | Z13: =S13 -> 0.87240858 | AA13: =MIN(1.1*Y13,Z13*Y13) -> 8.7240858 | AB13: 3 | AC13: =S13 -> 0.87240858 | AD13: =MIN(1.1*AB13,AC13*AB13) -> 2.6172257
A14: 6 | B14: Sinergi BUMN Untuk Mendukung Swasembada Gula | C14: C | E14: % | F14: 100 | G14: 100 | H14: 100 | I14: Maximize | J14: 7 | L14: =IFERROR(MIN(1.1*J14,(H14/G14)*J14),0) -> 7 | N14: =IFERROR(MIN(1.1*J14,(H14/F14)*J14),0) -> 7 | P14: =F14 -> 100 | Q14: =H14 -> 100 | R14: =J14 -> 7 | S14: =IFERROR(IF(I14="Minimize",F14/H14,IF(F14<=0,IF(H14>=F14,1.1,0),H14/F14)),0) -> 1 | T14: =MIN(1.1*R14,S14*R14) -> 7 | V14: 6 | W14: =S14 -> 1 | X14: =MIN(1.1*V14,W14*V14) -> 6 | Y14: 10 | Z14: =S14 -> 1 | AA14: =MIN(1.1*Y14,Z14*Y14) -> 10 | AB14: 3 | AC14: =S14 -> 1 | AD14: =MIN(1.1*AB14,AC14*AB14) -> 3
A15: A.3. Sosial | V15: =SUM(V16:V17) -> 10 | W15: =IFERROR(X15/V15,0) -> 1.012235 | X15: =SUM(X16:X17) -> 10.12235 | Y15: =SUM(Y16:Y17) -> 10 | Z15: =IFERROR(AA15/Y15,0) -> 1.012235 | AA15: =SUM(AA16:AA17) -> 10.12235 | AB15: =SUM(AB16:AB17) -> 10 | AC15: =IFERROR(AD15/AB15,0) -> 1.012235 | AD15: =SUM(AD16:AD17) -> 10.12235
A16: 7 | B16: Perolehan Bahan Baku P-3 Kelapa Sawit | C16: S | E16: Ton | F16: 3191756 | G16: 3191756 | H16: 3259110 | I16: Maximize | J16: 7 | K16: =SUM(J16:J17) -> 15 | L16: =IFERROR(MIN(1.1*J16,(H16/G16)*J16),0) -> 7.1477174 | M16: =SUM(L16:L17) -> 15.174658 | N16: =IFERROR(MIN(1.1*J16,(H16/F16)*J16),0) -> 7.1477174 | O16: =SUM(N16:N17) -> 15.174658 | P16: =F16 -> 3191756 | Q16: =H16 -> 3259110 | R16: =J16 -> 7 | S16: =IFERROR(IF(I16="Minimize",F16/H16,IF(F16<=0,IF(H16>=F16,1.1,0),H16/F16)),0) -> 1.0211025 | T16: =MIN(1.1*R16,S16*R16) -> 7.1477174 | V16: 5 | W16: =S16 -> 1.0211025 | X16: =MIN(1.1*V16,W16*V16) -> 5.1055125 | Y16: 5 | Z16: =S16 -> 1.0211025 | AA16: =MIN(1.1*Y16,Z16*Y16) -> 5.1055125 | AB16: 5 | AC16: =S16 -> 1.0211025 | AD16: =MIN(1.1*AB16,AC16*AB16) -> 5.1055125
A17: 8 | B17: Peremajaan Sawit Rakyat Sebagai Komitmen PSN | C17: S | E17: Ha | F17: 22568 | G17: 22568 | H17: 22644 | I17: Maximize | J17: 8 | L17: =IFERROR(MIN(1.1*J17,(H17/G17)*J17),0) -> 8.0269408 | N17: =IFERROR(MIN(1.1*J17,(H17/F17)*J17),0) -> 8.0269408 | P17: =F17 -> 22568 | Q17: =H17 -> 22644 | R17: =J17 -> 8 | S17: =IFERROR(IF(I17="Minimize",F17/H17,IF(F17<=0,IF(H17>=F17,1.1,0),H17/F17)),0) -> 1.0033676 | T17: =MIN(1.1*R17,S17*R17) -> 8.0269408 | V17: 5 | W17: =S17 -> 1.0033676 | X17: =MIN(1.1*V17,W17*V17) -> 5.016838 | Y17: 5 | Z17: =S17 -> 1.0033676 | AA17: =MIN(1.1*Y17,Z17*Y17) -> 5.016838 | AB17: 5 | AC17: =S17 -> 1.0033676 | AD17: =MIN(1.1*AB17,AC17*AB17) -> 5.016838
A18: B. Inovasi Model Bisnis | V18: =SUM(V19:V21) -> 15 | W18: =IFERROR(X18/V18,0) -> 0.86583629 | X18: =SUM(X19:X21) -> 12.987544 | Y18: =SUM(Y19:Y21) -> 15 | Z18: =IFERROR(AA18/Y18,0) -> 0.86583629 | AA18: =SUM(AA19:AA21) -> 12.987544 | AB18: =SUM(AB19:AB21) -> 15 | AC18: =IFERROR(AD18/AB18,0) -> 0.86583629 | AD18: =SUM(AD19:AD21) -> 12.987544
A19: 1 | B19: Sertifikasi RSPO PKS | C19: E | E19: Unit | F19: 68 | G19: 68 | H19: 67 | I19: Maximize | J19: 5 | K19: =J19+J20+J21 -> 15 | L19: =IFERROR(MIN(1.1*J19,(H19/G19)*J19),0) -> 4.9264706 | M19: =SUM(L19:L21) -> 12.987544 | N19: =IFERROR(MIN(1.1*J19,(H19/F19)*J19),0) -> 4.9264706 | O19: =SUM(N19:N21) -> 12.987544 | P19: =F19 -> 68 | Q19: =H19 -> 67 | R19: =J19 -> 5 | S19: =IFERROR(IF(I19="Minimize",F19/H19,IF(F19<=0,IF(H19>=F19,1.1,0),H19/F19)),0) -> 0.98529412 | T19: =MIN(1.1*R19,S19*R19) -> 4.9264706 | V19: 5 | W19: =S19 -> 0.98529412 | X19: =MIN(1.1*V19,W19*V19) -> 4.9264706 | Y19: 5 | Z19: =S19 -> 0.98529412 | AA19: =MIN(1.1*Y19,Z19*Y19) -> 4.9264706 | AB19: 5 | AC19: =S19 -> 0.98529412 | AD19: =MIN(1.1*AB19,AC19*AB19) -> 4.9264706
A20: 2 | B20: Sertifikasi RSPO Kebun | C20: E | E20: Unit | F20: 149 | G20: 149 | H20: 124 | I20: Maximize | J20: 5 | L20: =IFERROR(MIN(1.1*J20,(H20/G20)*J20),0) -> 4.1610738 | N20: =IFERROR(MIN(1.1*J20,(H20/F20)*J20),0) -> 4.1610738 | P20: =F20 -> 149 | Q20: =H20 -> 124 | R20: =J20 -> 5 | S20: =IFERROR(IF(I20="Minimize",F20/H20,IF(F20<=0,IF(H20>=F20,1.1,0),H20/F20)),0) -> 0.83221477 | T20: =MIN(1.1*R20,S20*R20) -> 4.1610738 | V20: 5 | W20: =S20 -> 0.83221477 | X20: =MIN(1.1*V20,W20*V20) -> 4.1610738 | Y20: 5 | Z20: =S20 -> 0.83221477 | AA20: =MIN(1.1*Y20,Z20*Y20) -> 4.1610738 | AB20: 5 | AC20: =S20 -> 0.83221477 | AD20: =MIN(1.1*AB20,AC20*AB20) -> 4.1610738
A21: 3 | B21: Implementasi Post Merger Integration | C21: C | E21: % | F21: 100 | G21: 100 | H21: 78 | I21: Maximize | J21: 5 | L21: =IFERROR(MIN(1.1*J21,(H21/G21)*J21),0) -> 3.9 | N21: =IFERROR(MIN(1.1*J21,(H21/F21)*J21),0) -> 3.9 | P21: =F21 -> 100 | Q21: =H21 -> 78 | R21: =J21 -> 5 | S21: =IFERROR(IF(I21="Minimize",F21/H21,IF(F21<=0,IF(H21>=F21,1.1,0),H21/F21)),0) -> 0.78 | T21: =MIN(1.1*R21,S21*R21) -> 3.9 | V21: 5 | W21: =S21 -> 0.78 | X21: =MIN(1.1*V21,W21*V21) -> 3.9 | Y21: 5 | Z21: =S21 -> 0.78 | AA21: =MIN(1.1*Y21,Z21*Y21) -> 3.9 | AB21: 5 | AC21: =S21 -> 0.78 | AD21: =MIN(1.1*AB21,AC21*AB21) -> 3.9
A22: C. Kepemimpinan Teknologi | V22: =V23 -> 10 | W22: =IFERROR(X22/V22,0) -> 1 | X22: =X23 -> 10 | Y22: =Y23 -> 10 | Z22: =IFERROR(AA22/Y22,0) -> 1 | AA22: =AA23 -> 10 | AB22: =AB23 -> 10 | AC22: =IFERROR(AD22/AB22,0) -> 1 | AD22: =AD23 -> 10
A23: 1 | B23: Implementasi Use Case Dalam RSTI 2025 - 2029 | C23: C | E23: % | F23: 100 | G23: 100 | H23: 100 | I23: Maximize | J23: 8 | K23: =J23 -> 8 | L23: =IFERROR(MIN(1.1*J23,(H23/G23)*J23),0) -> 8 | M23: =SUM(L23) -> 8 | N23: =IFERROR(MIN(1.1*J23,(H23/F23)*J23),0) -> 8 | O23: =SUM(N23) -> 8 | P23: =F23 -> 100 | Q23: =H23 -> 100 | R23: =J23 -> 8 | S23: =IFERROR(IF(I23="Minimize",F23/H23,IF(F23<=0,IF(H23>=F23,1.1,0),H23/F23)),0) -> 1 | T23: =MIN(1.1*R23,S23*R23) -> 8 | V23: 10 | W23: =S23 -> 1 | X23: =MIN(1.1*V23,W23*V23) -> 10 | Y23: 10 | Z23: =S23 -> 1 | AA23: =MIN(1.1*Y23,Z23*Y23) -> 10 | AB23: 10 | AC23: =S23 -> 1 | AD23: =MIN(1.1*AB23,AC23*AB23) -> 10
A24: D. Peningkatan Investasi | V24: =SUM(V25:V26) -> 15 | W24: =IFERROR(X24/V24,0) -> 0.87846248 | X24: =SUM(X25:X26) -> 13.176937 | Y24: =SUM(Y25:Y26) -> 15 | Z24: =IFERROR(AA24/Y24,0) -> 0.87846248 | AA24: =SUM(AA25:AA26) -> 13.176937 | AB24: =SUM(AB25:AB26) -> 15 | AC24: =IFERROR(AD24/AB24,0) -> 0.87846248 | AD24: =SUM(AD25:AD26) -> 13.176937
A25: 1 | B25: Replanting & Konversi | C25: C | E25: Ha | F25: 41842 | G25: 41842 | H25: 38288.5 | I25: Maximize | J25: 8 | K25: =J25+J26 -> 15 | L25: =IFERROR(MIN(1.1*J25,(H25/G25)*J25),0) -> 7.320587 | M25: =SUM(L25:L26) -> 13.176937 | N25: =IFERROR(MIN(1.1*J25,(H25/F25)*J25),0) -> 7.320587 | O25: =SUM(N25:N26) -> 13.176937 | P25: =F25 -> 41842 | Q25: =H25 -> 38288.5 | R25: =J25 -> 8 | S25: =IFERROR(IF(I25="Minimize",F25/H25,IF(F25<=0,IF(H25>=F25,1.1,0),H25/F25)),0) -> 0.91507337 | T25: =MIN(1.1*R25,S25*R25) -> 7.320587 | V25: 8 | W25: =S25 -> 0.91507337 | X25: =MIN(1.1*V25,W25*V25) -> 7.320587 | Y25: 8 | Z25: =S25 -> 0.91507337 | AA25: =MIN(1.1*Y25,Z25*Y25) -> 7.320587 | AB25: 8 | AC25: =S25 -> 0.91507337 | AD25: =MIN(1.1*AB25,AC25*AB25) -> 7.320587
A26: 2 | B26: Realisasi PMN | C26: S | E26: % | F26: 97.32 | G26: 97.32 | H26: 81.42 | I26: Maximize | J26: 7 | L26: =IFERROR(MIN(1.1*J26,(H26/G26)*J26),0) -> 5.8563502 | N26: =IFERROR(MIN(1.1*J26,(H26/F26)*J26),0) -> 5.8563502 | P26: =F26 -> 97.32 | Q26: =H26 -> 81.42 | R26: =J26 -> 7 | S26: =IFERROR(IF(I26="Minimize",F26/H26,IF(F26<=0,IF(H26>=F26,1.1,0),H26/F26)),0) -> 0.83662145 | T26: =MIN(1.1*R26,S26*R26) -> 5.8563502 | V26: 7 | W26: =S26 -> 0.83662145 | X26: =MIN(1.1*V26,W26*V26) -> 5.8563502 | Y26: 7 | Z26: =S26 -> 0.83662145 | AA26: =MIN(1.1*Y26,Z26*Y26) -> 5.8563502 | AB26: 7 | AC26: =S26 -> 0.83662145 | AD26: =MIN(1.1*AB26,AC26*AB26) -> 5.8563502
A27: E. Pengembangan Talenta | V27: =V28 -> 10 | W27: =IFERROR(X27/V27,0) -> 0.946 | X27: =X28 -> 9.46 | Y27: =Y28 -> 10 | Z27: =IFERROR(AA27/Y27,0) -> 0.946 | AA27: =AA28 -> 9.46 | AB27: =AB28 -> 10 | AC27: =IFERROR(AD27/AB27,0) -> 0.946 | AD27: =AD28 -> 9.46
A28: 1 | B28: Human Capital Transformation | C28: S | E28: % | F28: 100 | G28: 100 | H28: 94.6 | I28: Maximize | J28: 8 | K28: =J28 -> 8 | L28: =IFERROR(MIN(1.1*J28,(H28/G28)*J28),0) -> 7.568 | M28: =SUM(L28) -> 7.568 | N28: =IFERROR(MIN(1.1*J28,(H28/F28)*J28),0) -> 7.568 | O28: =SUM(N28) -> 7.568 | P28: =F28 -> 100 | Q28: =H28 -> 94.6 | R28: =J28 -> 8 | S28: =IFERROR(IF(I28="Minimize",F28/H28,IF(F28<=0,IF(H28>=F28,1.1,0),H28/F28)),0) -> 0.946 | T28: =MIN(1.1*R28,S28*R28) -> 7.568 | V28: 10 | W28: =S28 -> 0.946 | X28: =MIN(1.1*V28,W28*V28) -> 9.46 | Y28: 10 | Z28: =S28 -> 0.946 | AA28: =MIN(1.1*Y28,Z28*Y28) -> 9.46 | AB28: 10 | AC28: =S28 -> 0.946 | AD28: =MIN(1.1*AB28,AC28*AB28) -> 9.46
B29: TOTAL | K29: =SUM(K8,K12,K16,K19,K23,K25,K28) -> 100 | M29: =SUM(M8,M12,M16,M19,M23,M25,M28) -> 90.501845 | O29: =SUM(O8,O12,O16,O19,O23,O25,O28) -> 90.501845 | R29: =SUM(R8:R28) -> 100 | S29: =IFERROR(T29/R29,0) -> 0.90501845 | T29: =SUM(T8:T28) -> 90.501845 | V29: =V7+V11+V15+V18+V22+V24+V27 -> 100 | W29: =IFERROR(X29/V29,0) -> 0.90541537 | X29: =X7+X11+X15+X18+X22+X24+X27 -> 90.541537 | Y29: =Y7+Y11+Y15+Y18+Y22+Y24+Y27 -> 100 | Z29: =IFERROR(AA29/Y29,0) -> 0.91010697 | AA29: =AA7+AA11+AA15+AA18+AA22+AA24+AA27 -> 91.010697 | AB29: =AB7+AB11+AB15+AB18+AB22+AB24+AB27 -> 100 | AC29: =IFERROR(AD29/AB29,0) -> 0.89099969 | AD29: =AD7+AD11+AD15+AD18+AD22+AD24+AD27 -> 89.099969

Sheet PTPN IV
A1: Key Performance Indicator PT Perkebunan Nusantara IV
A2: s.d. Desember2025
A4: No. | B4: Key Performance Indicator | C4: ESG/C | D4: 88 PS | E4: Satuan | F4: Target 2025 | G4: Target s.d. Desember | H4: Realisasi s.d. Desember | I4: Polaritas | J4: Bobot | L4: Realisasi vs Target s.d. Desember | N4: Realisasi vs Target 2025 | P4: Target 2025 | Q4: Realisasi 2025 | R4: Bobot KPI | S4: % Capaian Realisasi | T4: Skor Realisasi KPI | V4: Region Head | Y4: SEVP Operation / Koordinator KSO / Operasional KSO / Aset | AB4: SEVP Business Support / Business Strategy
J5: Sub | K5: Total | L5: Sub | M5: Total | N5: Sub | O5: Total | V5: Bobot | W5: % Capaian | X5: Skor | Y5: Bobot | Z5: % Capaian | AA5: Skor | AB5: Bobot | AC5: % Capaian | AD5: Skor
A6: A. Nilai Ekonomi dan Sosial Untuk Indonesia
A7: A.1 Finansial
A8: 1 | B8: EBITDA Margin | C8: C | E8: % | F8: 21.92 | G8: 21.92 | H8: 26.15 | I8: Maximize | J8: 8 | K8: =J8+J9+J10 -> 18 | L8: =IFERROR(MIN(1.1*J8,(H8/G8)*J8),0) -> 8.8 | M8: =L8+L9+L10 -> 14.3 | N8: =IFERROR(MIN(1.1*J8,(H8/F8)*J8),0) -> 8.8 | O8: =N8+N9+N10 -> 14.3 | P8: =F8 -> 21.92 | Q8: =H8 -> 26.15 | R8: =J8 -> 8 | S8: =IFERROR(MAX(0,IF(I8="Minimize",F8/H8,IF(F8>0,H8/F8,IF(H8>0,1.1,F8/H8)))),0) -> 1.1929745 | T8: =MIN(1.1*R8,S8*R8) -> 8.8 | V8: 9 | W8: =S8 -> 1.1929745 | X8: =MIN(1.1*V8,W8*V8) -> 9.9 | Y8: 4 | Z8: =S8 -> 1.1929745 | AA8: =MIN(1.1*Y8,Z8*Y8) -> 4.4 | AB8: 14 | AC8: =S8 -> 1.1929745 | AD8: =MIN(1.1*AB8,AC8*AB8) -> 15.4
A9: 2 | B9: ROIC >= WACC | C9: C | E9: % | F9: 3.8187418 | G9: 3.8187418 | H9: 9.72 | I9: Maximize | J9: 5 | L9: =IFERROR(MIN(1.1*J9,(H9/G9)*J9),0) -> 5.5 | N9: =IFERROR(MIN(1.1*J9,(H9/F9)*J9),0) -> 5.5 | P9: =F9 -> 3.8187418 | Q9: =H9 -> 9.72 | R9: =J9 -> 5 | S9: =IFERROR(MAX(0,IF(I9="Minimize",F9/H9,IF(F9>0,H9/F9,IF(H9>0,1.1,F9/H9)))),0) -> 2.545341 | T9: =MIN(1.1*R9,S9*R9) -> 5.5 | V9: 6 | W9: =S9 -> 2.545341 | X9: =MIN(1.1*V9,W9*V9) -> 6.6 | Y9: 3 | Z9: =S9 -> 2.545341 | AA9: =MIN(1.1*Y9,Z9*Y9) -> 3.3 | AB9: 8 | AC9: =S9 -> 2.545341 | AD9: =MIN(1.1*AB9,AC9*AB9) -> 8.8
A10: 3 | B10: Penyampaian LAI Tahun 2025 | C10: G | E10: Waktu | F10: 45747 | G10: 45748 | H10: 45748 | I10: Minimize | J10: 5 | L10: =IFERROR(MIN(1.1*J10,(F10/D10)*J10),0) -> 0 | N10: =IFERROR(MIN(1.1*L10,(H10/F10)*L10),0) -> 0 | P10: =F10 -> 45747 | Q10: =H10 -> 45748 | R10: =J10 -> 5 | S10: =IFERROR(T10/R10,0) -> 1 | T10: =R10*IF(H10<DATE(2025,4,1),1.1,IF(H10<=DATE(2025,4,15),1,IF(H10<=DATE(2025,5,31),0.8,IF(H10<=DATE(2025,6,15),0.4,IF(H10<=DATE(2025,6,30),0.2,0))))) -> 5 | V10: 5 | W10: =S10 -> 1 | X10: =MIN(1.1*V10,W10*V10) -> 5 | Y10: 3 | Z10: =S10 -> 1 | AA10: =MIN(1.1*Y10,Z10*Y10) -> 3 | AB10: 8 | AC10: =S10 -> 1 | AD10: =MIN(1.1*AB10,AC10*AB10) -> 8
A11: A.2. Operasional
A12: 4 | B12: Cash Cost Kelapa Sawit | C12: C | E12: Rp/Kg | F12: 4630.8 | G12: 4630.8 | H12: 4405 | I12: Minimize | J12: 10 | K12: =SUM(J12:J13) -> 20 | L12: =IFERROR(MIN(1.1*J12,(G12/H12)*J12),0) -> 10.512599 | M12: =SUM(L12,L13) -> 19.353841 | N12: =IFERROR(MIN(1.1*J12,(F12/H12)*J12),0) -> 10.512599 | O12: =SUM(N12,N13) -> 19.353841 | P12: =F12 -> 4630.8 | Q12: =H12 -> 4405 | R12: =J12 -> 10 | S12: =IFERROR(MAX(0,IF(I12="Minimize",F12/H12,IF(F12>0,H12/F12,IF(H12>0,1.1,F12/H12)))),0) -> 1.0512599 | T12: =MIN(1.1*R12,S12*R12) -> 10.512599 | V12: 10 | W12: =S12 -> 1.0512599 | X12: =MIN(1.1*V12,W12*V12) -> 10.512599 | Y12: 15 | Z12: =S12 -> 1.0512599 | AA12: =MIN(1.1*Y12,Z12*Y12) -> 15.768899 | AB12: 5 | AC12: =S12 -> 1.0512599 | AD12: =MIN(1.1*AB12,AC12*AB12) -> 5.2562997
A13: 5 | B13: Produktivitas CPO | C13: C | E13: Ton/Ha | F13: 5.4291019 | G13: 5.4291019 | H13: 4.8 | I13: Maximize | J13: 10 | L13: =IFERROR(MIN(1.1*J13,(H13/G13)*J13),0) -> 8.8412413 | N13: =IFERROR(MIN(1.1*J13,(H13/F13)*J13),0) -> 8.8412413 | P13: =F13 -> 5.4291019 | Q13: =H13 -> 4.8 | R13: =J13 -> 10 | S13: =IFERROR(MAX(0,IF(I13="Minimize",F13/H13,IF(F13>0,H13/F13,IF(H13>0,1.1,F13/H13)))),0) -> 0.88412413 | T13: =MIN(1.1*R13,S13*R13) -> 8.8412413 | V13: 10 | W13: =S13 -> 0.88412413 | X13: =MIN(1.1*V13,W13*V13) -> 8.8412413 | Y13: 15 | Z13: =S13 -> 0.88412413 | AA13: =MIN(1.1*Y13,Z13*Y13) -> 13.261862 | AB13: 5 | AC13: =S13 -> 0.88412413 | AD13: =MIN(1.1*AB13,AC13*AB13) -> 4.4206207
A14: A.3. Sosial
A15: 6 | B15: Perolehan Bahan Baku P-3 Kelapa Sawit | C15: S | E15: Ton | F15: 3191757 | G15: 3191757 | H15: 3259110 | I15: Maximize | J15: 8 | K15: =SUM(J15:J16) -> 16 | L15: =IFERROR(MIN(1.1*J15,(H15/G15)*J15),0) -> 8.1688175 | M15: =SUM(L15,L16) -> 16.388598 | N15: =IFERROR(MIN(1.1*J15,(H15/F15)*J15),0) -> 8.1688175 | O15: =SUM(N15,N16) -> 16.388598 | P15: =F15 -> 3191757 | Q15: =H15 -> 3259110 | R15: =J15 -> 8 | S15: =IFERROR(MAX(0,IF(I15="Minimize",F15/H15,IF(F15>0,H15/F15,IF(H15>0,1.1,F15/H15)))),0) -> 1.0211022 | T15: =MIN(1.1*R15,S15*R15) -> 8.1688175 | V15: 5 | W15: =S15 -> 1.0211022 | X15: =MIN(1.1*V15,W15*V15) -> 5.1055109 | Y15: 5 | Z15: =S15 -> 1.0211022 | AA15: =MIN(1.1*Y15,Z15*Y15) -> 5.1055109 | AB15: 5 | AC15: =S15 -> 1.0211022 | AD15: =MIN(1.1*AB15,AC15*AB15) -> 5.1055109
A16: 7 | B16: Peremajaan Sawit Rakyat Sebagai Komitmen PSN | C16: S | E16: Ha | F16: 22568 | G16: 22568 | H16: 23188 | I16: Maximize | J16: 8 | L16: =IFERROR(MIN(1.1*J16,(H16/G16)*J16),0) -> 8.2197802 | N16: =IFERROR(MIN(1.1*J16,(H16/F16)*J16),0) -> 8.2197802 | P16: =F16 -> 22568 | Q16: =H16 -> 23188 | R16: =J16 -> 8 | S16: =IFERROR(MAX(0,IF(I16="Minimize",F16/H16,IF(F16>0,H16/F16,IF(H16>0,1.1,F16/H16)))),0) -> 1.0274725 | T16: =MIN(1.1*R16,S16*R16) -> 8.2197802 | V16: 5 | W16: =S16 -> 1.0274725 | X16: =MIN(1.1*V16,W16*V16) -> 5.1373626 | Y16: 5 | Z16: =S16 -> 1.0274725 | AA16: =MIN(1.1*Y16,Z16*Y16) -> 5.1373626 | AB16: 5 | AC16: =S16 -> 1.0274725 | AD16: =MIN(1.1*AB16,AC16*AB16) -> 5.1373626
A17: B. Inovasi Model Bisnis
A18: 1 | B18: Sertifikasi RSPO | C18: E | E18: Unit | F18: 217 | G18: 217 | H18: 191 | I18: Maximize | J18: 4 | K18: =SUM(J18:J21) -> 15 | L18: =IFERROR(MIN(1.1*J18,(H18/G18)*J18),0) -> 3.5207373 | M18: =SUM(L18:L21) -> 14.920737 | N18: =IFERROR(MIN(1.1*J18,(H18/F18)*J18),0) -> 3.5207373 | O18: =SUM(N18:N21) -> 14.920737 | P18: =F18 -> 217 | Q18: =H18 -> 191 | R18: =J18 -> 4 | S18: =IFERROR(MAX(0,IF(I18="Minimize",F18/H18,IF(F18>0,H18/F18,IF(H18>0,1.1,F18/H18)))),0) -> 0.88018433 | T18: =MIN(1.1*R18,S18*R18) -> 3.5207373 | V18: 4 | W18: =S18 -> 0.88018433 | X18: =MIN(1.1*V18,W18*V18) -> 3.5207373 | Y18: 4 | Z18: =S18 -> 0.88018433 | AA18: =MIN(1.1*Y18,Z18*Y18) -> 3.5207373 | AB18: 4 | AC18: =S18 -> 0.88018433 | AD18: =MIN(1.1*AB18,AC18*AB18) -> 3.5207373
A19: 2 | B19: Total Revenue dari Pemasaran Produk | C19: C | E19: Rp Miliar | F19: 41404 | G19: 41404 | H19: 46387 | I19: Maximize | J19: 4 | L19: =IFERROR(MIN(1.1*J19,(H19/G19)*J19),0) -> 4.4 | N19: =IFERROR(MIN(1.1*J19,(H19/F19)*J19),0) -> 4.4 | P19: =F19 -> 41404 | Q19: =H19 -> 46387 | R19: =J19 -> 4 | S19: =IFERROR(MAX(0,IF(I19="Minimize",F19/H19,IF(F19>0,H19/F19,IF(H19>0,1.1,F19/H19)))),0) -> 1.1203507 | T19: =MIN(1.1*R19,S19*R19) -> 4.4 | V19: 4 | W19: =S19 -> 1.1203507 | X19: =MIN(1.1*V19,W19*V19) -> 4.4 | Y19: 4 | Z19: =S19 -> 1.1203507 | AA19: =MIN(1.1*Y19,Z19*Y19) -> 4.4 | AB19: 4 | AC19: =S19 -> 1.1203507 | AD19: =MIN(1.1*AB19,AC19*AB19) -> 4.4
A20: 3 | B20: Pengukuran Nilai Emisi Karbon | C20: E | E20: % | F20: 100 | G20: 100 | H20: 100 | I20: Maximize | J20: 3 | L20: =IFERROR(MIN(1.1*J20,(H20/G20)*J20),0) -> 3 | N20: =IFERROR(MIN(1.1*J20,(H20/F20)*J20),0) -> 3 | P20: =F20 -> 100 | Q20: =H20 -> 100 | R20: =J20 -> 3 | S20: =IFERROR(MAX(0,IF(I20="Minimize",F20/H20,IF(F20>0,H20/F20,IF(H20>0,1.1,F20/H20)))),0) -> 1 | T20: =MIN(1.1*R20,S20*R20) -> 3 | V20: 3 | W20: =S20 -> 1 | X20: =MIN(1.1*V20,W20*V20) -> 3 | Y20: 3 | Z20: =S20 -> 1 | AA20: =MIN(1.1*Y20,Z20*Y20) -> 3 | AB20: 3 | AC20: =S20 -> 1 | AD20: =MIN(1.1*AB20,AC20*AB20) -> 3
A21: 4 | B21: Implementasi Post Merger Integration | C21: C | E21: % | F21: 100 | G21: 100 | H21: 100 | I21: Maximize | J21: 4 | L21: =IFERROR(MIN(1.1*J21,(H21/G21)*J21),0) -> 4 | N21: =IFERROR(MIN(1.1*J21,(H21/F21)*J21),0) -> 4 | P21: =F21 -> 100 | Q21: =H21 -> 100 | R21: =J21 -> 4 | S21: =IFERROR(MAX(0,IF(I21="Minimize",F21/H21,IF(F21>0,H21/F21,IF(H21>0,1.1,F21/H21)))),0) -> 1 | T21: =MIN(1.1*R21,S21*R21) -> 4 | V21: 4 | W21: =S21 -> 1 | X21: =MIN(1.1*V21,W21*V21) -> 4 | Y21: 4 | Z21: =S21 -> 1 | AA21: =MIN(1.1*Y21,Z21*Y21) -> 4 | AB21: 4 | AC21: =S21 -> 1 | AD21: =MIN(1.1*AB21,AC21*AB21) -> 4
A22: C. Kepemimpinan Teknologi
